<?xml version="1.0"?>
<robot name="rolling_robot">

  <material name="grey">
    <color rgba="0.5 0.5 0.5 0.5"/>
  </material>
  
  <link name="dummy">
  </link>
  
  <link name="base_link">
    <visual>
      <geometry>
	<mesh filename="/home/eric/rolling_robot/rolling_robot_model/rhombicuboctahedron.stl" scale="0.025641 0.025641 0.025641"/>
      </geometry>
      <origin xyz="0 0 0"/>
      <material name="grey"/>
    </visual>
    <collision>
      <geometry>
	<mesh filename="/home/eric/rolling_robot/rolling_robot_model/rhombicuboctahedron.stl" scale="0.025641 0.025641 0.025641"/>
      </geometry>
    </collision>
    <inertial>
      <mass value="20"/>
      <inertia ixx="3.3334" ixy="0.0" ixz="0.0" iyy="3.3334" iyz="0.0" izz="3.3334"/>
    </inertial>
  </link>
  
  <joint name="dummy_joint" type="fixed">
     <parent link="dummy"/>
     <child link="base_link"/>
   </joint>

  <link name="link1">
    <visual>
      <geometry>
        <cylinder length="0.1778" radius="0.005"/>
      </geometry>
      <origin rpy="-0.392699 -0 -0" xyz="0 -0.094 -0.224703"/>
      <material name="grey"/>
    </visual>
    <collision>
      <geometry>
	    <cylinder length="0.1778" radius="0.005"/>
      </geometry>
      <origin rpy="-0.392699 -0 -0" xyz="0 -0.094 -0.224703"/>
    </collision>
    <inertial>
      <mass value="0.1"/>
    <inertia ixx="0.00026407" ixy="0.0" ixz="0.0" iyy="0.00026407" iyz="0.0" izz="0.00026407"/>
    </inertial>
  </link>

  <link name="link2">
    <visual>
      <geometry>
        <cylinder length="0.1778" radius="0.005"/>
      </geometry>
      <origin rpy="0.392699 -0 -0" xyz="0 0.094 -0.224703"/>
      <material name="grey"/>
    </visual>
    <collision>
      <geometry>
	    <cylinder length="0.1778" radius="0.005"/>
      </geometry>
      <origin rpy="0.392699 -0 -0" xyz="0 0.094 -0.224703"/>
    </collision>
    <inertial>
      <mass value="0.1"/>
    <inertia ixx="0.00026407" ixy="0.0" ixz="0.0" iyy="0.00026407" iyz="0.0" izz="0.00026407"/>
    </inertial>
  </link>

  <link name="link3">
    <visual>
      <geometry>
        <cylinder length="0.1778" radius="0.005"/>
      </geometry>
      <origin rpy="1.178097 0 0" xyz="0 0.221 -0.088000"/>
      <material name="grey"/>
    </visual>
    <collision>
      <geometry>
	    <cylinder length="0.1778" radius="0.005"/>
      </geometry>
      <origin rpy="1.178097 0 0" xyz="0 0.221 -0.088000"/>
    </collision>
    <inertial>
      <mass value="0.1"/>
    <inertia ixx="0.00026407" ixy="0.0" ixz="0.0" iyy="0.00026407" iyz="0.0" izz="0.00026407"/>
    </inertial>
  </link>


  <link name="link4">
    <visual>
      <geometry>
        <cylinder length="0.1778" radius="0.005"/>
      </geometry>
      <origin rpy="1.963495 0 0" xyz="0 0.221 0.088000"/>
      <material name="grey"/>
    </visual>
    <collision>
      <geometry>
	    <cylinder length="0.1778" radius="0.005"/>
      </geometry>
      <origin rpy="1.963495 0 0" xyz="0 0.221 0.088000"/>
    </collision>
    <inertial>
      <mass value="0.1"/>
    <inertia ixx="0.00026407" ixy="0.0" ixz="0.0" iyy="0.00026407" iyz="0.0" izz="0.00026407"/>
    </inertial>
  </link>

  <link name="link5">
    <visual>
      <geometry>
        <cylinder length="0.1778" radius="0.005"/>
      </geometry>
      <origin rpy="2.748894 0 0" xyz="0 0.094 0.224703"/>
      <material name="grey"/>
    </visual>
    <collision>
      <geometry>
	    <cylinder length="0.1778" radius="0.005"/>
      </geometry>
      <origin rpy="2.748894 0 0" xyz="0 0.094 0.224703"/>
    </collision>
    <inertial>
      <mass value="0.1"/>
    <inertia ixx="0.00026407" ixy="0.0" ixz="0.0" iyy="0.00026407" iyz="0.0" izz="0.00026407"/>
    </inertial>
  </link>
 
  <link name="link6">
    <visual>
      <geometry>
        <cylinder length="0.1778" radius="0.005"/>
      </geometry>
      <origin rpy="-2.748894 0 0" xyz="0 -0.094 0.224703"/>
      <material name="grey"/>
    </visual>
    <collision>
      <geometry>
	    <cylinder length="0.1778" radius="0.005"/>
      </geometry>
      <origin rpy="-2.748894 0 0" xyz="0 -0.094 0.224703"/>
    </collision>
    <inertial>
      <mass value="0.1"/>
    <inertia ixx="0.00026407" ixy="0.0" ixz="0.0" iyy="0.00026407" iyz="0.0" izz="0.00026407"/>
    </inertial>
  </link>

  <link name="link7">
    <visual>
      <geometry>
        <cylinder length="0.1778" radius="0.005"/>
      </geometry>
      <origin rpy="-1.963495 0 0" xyz="0 -0.221 0.088000"/>
      <material name="grey"/>
    </visual>
    <collision>
      <geometry>
	    <cylinder length="0.1778" radius="0.005"/>
      </geometry>
      <origin rpy="-1.963495 0 0" xyz="0 -0.221 0.088000"/>
    </collision>
    <inertial>
      <mass value="0.1"/>
    <inertia ixx="0.00026407" ixy="0.0" ixz="0.0" iyy="0.00026407" iyz="0.0" izz="0.00026407"/>
    </inertial>
  </link>

  <link name="link8">
    <visual>
      <geometry>
        <cylinder length="0.1778" radius="0.005"/>
      </geometry>
      <origin rpy="-1.178097 0 0" xyz="0 -0.221 -0.088000"/>
      <material name="grey"/>
    </visual>
    <collision>
      <geometry>
	    <cylinder length="0.1778" radius="0.005"/>
      </geometry>
      <origin rpy="-1.178097 0 0" xyz="0 -0.221 -0.088000"/>
    </collision>
    <inertial>
      <mass value="0.1"/>
    <inertia ixx="0.00026407" ixy="0.0" ixz="0.0" iyy="0.00026407" iyz="0.0" izz="0.00026407"/>
    </inertial>
  </link>

  <link name="link9">
    <visual>
      <geometry>
        <cylinder length="0.1778" radius="0.005"/>
      </geometry>
      <origin rpy="0 0.392699 -0" xyz="-0.094 0 -0.224703"/>
      <material name="grey"/>
    </visual>
    <collision>
      <geometry>
	    <cylinder length="0.1778" radius="0.005"/>
      </geometry>
      <origin rpy="0 0.392699 -0" xyz="-0.094 0 -0.224703"/>
    </collision>
    <inertial>
      <mass value="0.1"/>
    <inertia ixx="0.00026407" ixy="0.0" ixz="0.0" iyy="0.00026407" iyz="0.0" izz="0.00026407"/>
    </inertial>
  </link>

  <link name="link10">
    <visual>
      <geometry>
        <cylinder length="0.1778" radius="0.005"/>
      </geometry>
      <origin rpy="0 -0.392699 -0" xyz="0.094 0 -0.224703"/>
      <material name="grey"/>
    </visual>
    <collision>
      <geometry>
	    <cylinder length="0.1778" radius="0.005"/>
      </geometry>
      <origin rpy="0 -0.392699 -0" xyz="0.094 0 -0.224703"/>
    </collision>
    <inertial>
      <mass value="0.1"/>
    <inertia ixx="0.00026407" ixy="0.0" ixz="0.0" iyy="0.00026407" iyz="0.0" izz="0.00026407"/>
    </inertial>
  </link>

  <link name="link11">
    <visual>
      <geometry>
        <cylinder length="0.1778" radius="0.005"/>
      </geometry>
      <origin rpy="0 -1.178097 0" xyz="0.221 0 -0.088000"/>
      <material name="grey"/>
    </visual>
    <collision>
      <geometry>
	    <cylinder length="0.1778" radius="0.005"/>
      </geometry>
      <origin rpy="0 -1.178097 0" xyz="0.221 0 -0.088000"/>
    </collision>
    <inertial>
      <mass value="0.1"/>
    <inertia ixx="0.00026407" ixy="0.0" ixz="0.0" iyy="0.00026407" iyz="0.0" izz="0.00026407"/>
    </inertial>
  </link>

  <link name="link12">
    <visual>
      <geometry>
        <cylinder length="0.1778" radius="0.005"/>
      </geometry>
      <origin rpy="0 -1.963495 0" xyz="0.221 0 0.088000"/>
      <material name="grey"/>
    </visual>
    <collision>
      <geometry>
	    <cylinder length="0.1778" radius="0.005"/>
      </geometry>
      <origin rpy="0 -1.963495 0" xyz="0.221 0 0.088000"/>
    </collision>
    <inertial>
      <mass value="0.1"/>
    <inertia ixx="0.00026407" ixy="0.0" ixz="0.0" iyy="0.00026407" iyz="0.0" izz="0.00026407"/>
    </inertial>
  </link>

  <link name="link13">
    <visual>
      <geometry>
        <cylinder length="0.1778" radius="0.005"/>
      </geometry>
      <origin rpy="0 -2.748894 0" xyz="0.094 0 0.224703"/>
      <material name="grey"/>
    </visual>
    <collision>
      <geometry>
	    <cylinder length="0.1778" radius="0.005"/>
      </geometry>
      <origin rpy="0 -2.748894 0" xyz="0.094 0 0.224703"/>
    </collision>
    <inertial>
      <mass value="0.1"/>
    <inertia ixx="0.00026407" ixy="0.0" ixz="0.0" iyy="0.00026407" iyz="0.0" izz="0.00026407"/>
    </inertial>
  </link>

  <link name="link14">
    <visual>
      <geometry>
        <cylinder length="0.1778" radius="0.005"/>
      </geometry>
      <origin rpy="0 2.748894 0" xyz="-0.094 0 0.224703"/>
      <material name="grey"/>
    </visual>
    <collision>
      <geometry>
	    <cylinder length="0.1778" radius="0.005"/>
      </geometry>
      <origin rpy="0 2.748894 0" xyz="-0.094 0 0.224703"/>
    </collision>
    <inertial>
      <mass value="0.1"/>
    <inertia ixx="0.00026407" ixy="0.0" ixz="0.0" iyy="0.00026407" iyz="0.0" izz="0.00026407"/>
    </inertial>
  </link>

  <link name="link15">
    <visual>
      <geometry>
        <cylinder length="0.1778" radius="0.005"/>
      </geometry>
      <origin rpy="0 1.963495 0" xyz="-0.221 0 0.088000"/>
      <material name="grey"/>
    </visual>
    <collision>
      <geometry>
	    <cylinder length="0.1778" radius="0.005"/>
      </geometry>
      <origin rpy="0 1.963495 0" xyz="-0.221 0 0.088000"/>
    </collision>
    <inertial>
      <mass value="0.1"/>
    <inertia ixx="0.00026407" ixy="0.0" ixz="0.0" iyy="0.00026407" iyz="0.0" izz="0.00026407"/>
    </inertial>
  </link>

  <link name="link16">
    <visual>
      <geometry>
        <cylinder length="0.1778" radius="0.005"/>
      </geometry>
      <origin rpy="0 1.178097 0" xyz="-0.221 0 -0.088000"/>
      <material name="grey"/>
    </visual>
    <collision>
      <geometry>
	    <cylinder length="0.1778" radius="0.005"/>
      </geometry>
      <origin rpy="0 1.178097 0" xyz="-0.221 0 -0.088000"/>
    </collision>
    <inertial>
      <mass value="0.1"/>
    <inertia ixx="0.00026407" ixy="0.0" ixz="0.0" iyy="0.00026407" iyz="0.0" izz="0.00026407"/>
    </inertial>
  </link>

  <joint name="joint1" type="prismatic">
    <parent link="base_link"/>
    <child link="link1"/>
    <origin xyz="0 0 0"/>
    <axis xyz="0 -0.382683 -0.923880"/>
    <limit effort="10000000" lower="0.0" upper="0.1778" velocity="1000"/>
  </joint>

  <joint name="joint2" type="prismatic">
    <parent link="base_link"/>
    <child link="link2"/>
    <origin xyz="0 0 0"/>
    <axis xyz="0 0.382683 -0.923880"/>
    <limit effort="10000000" lower="0.0" upper="0.1778" velocity="1000"/>
  </joint>

  <joint name="joint3" type="prismatic">
    <parent link="base_link"/>
    <child link="link3"/>
    <origin xyz="0 0 0"/>
    <axis xyz="0 0.923879 -0.382683"/>
    <limit effort="10000000" lower="0.0" upper="0.1778" velocity="1000"/>
  </joint>

  <joint name="joint4" type="prismatic">
    <parent link="base_link"/>
    <child link="link4"/>
    <origin xyz="0 0 0"/>
    <axis xyz="0 0.923879 0.382683"/>
    <limit effort="10000000" lower="0.0" upper="0.1778" velocity="1000"/>
  </joint>

  <joint name="joint5" type="prismatic">
    <parent link="base_link"/>
    <child link="link5"/>
    <origin xyz="0 0 0"/>
    <axis xyz="0 0.382683 0.923880"/>
    <limit effort="10000000" lower="0.0" upper="0.1778" velocity="1000"/>
  </joint>

  <joint name="joint6" type="prismatic">
    <parent link="base_link"/>
    <child link="link6"/>
    <origin xyz="0 0 0"/>
    <axis xyz="0 -0.382683 0.923880"/>
    <limit effort="10000000" lower="0.0" upper="0.1778" velocity="1000"/>
  </joint>

  <joint name="joint7" type="prismatic">
    <parent link="base_link"/>
    <child link="link7"/>
    <origin xyz="0 0 0"/>
    <axis xyz="0 -0.923879 0.382683"/>
    <limit effort="10000000" lower="0.0" upper="0.1778" velocity="1000"/>
  </joint>

  <joint name="joint8" type="prismatic">
    <parent link="base_link"/>
    <child link="link8"/>
    <origin xyz="0 0 0"/>
    <axis xyz="0 -0.923879 -0.382683"/>
    <limit effort="10000000" lower="0.0" upper="0.1778" velocity="1000"/>
  </joint>

  <joint name="joint9" type="prismatic">
    <parent link="base_link"/>
    <child link="link9"/>
    <origin xyz="0 0 0"/>
    <axis xyz="-0.382683 0 -0.923880"/>
    <limit effort="10000000" lower="0.0" upper="0.1778" velocity="1000"/>
  </joint>

  <joint name="joint10" type="prismatic">
    <parent link="base_link"/>
    <child link="link10"/>
    <origin xyz="0 0 0"/>
    <axis xyz="0.382683 0 -0.923880"/>
    <limit effort="10000000" lower="0.0" upper="0.1778" velocity="1000"/>
  </joint>

  <joint name="joint11" type="prismatic">
    <parent link="base_link"/>
    <child link="link11"/>
    <origin xyz="0 0 0"/>
    <axis xyz="0.923879 0 -0.382683"/>
    <limit effort="10000000" lower="0.0" upper="0.1778" velocity="1000"/>
  </joint>

  <joint name="joint12" type="prismatic">
    <parent link="base_link"/>
    <child link="link12"/>
    <origin xyz="0 0 0"/>
    <axis xyz="0.923879 0 0.382683"/>
    <limit effort="10000000" lower="0.0" upper="0.1778" velocity="1000"/>
  </joint>

  <joint name="joint13" type="prismatic">
    <parent link="base_link"/>
    <child link="link13"/>
    <origin xyz="0 0 0"/>
    <axis xyz="0.382683 0 0.923880"/>
    <limit effort="10000000" lower="0.0" upper="0.1778" velocity="1000"/>
  </joint>

  <joint name="joint14" type="prismatic">
    <parent link="base_link"/>
    <child link="link14"/>
    <origin xyz="0 0 0"/>
    <axis xyz="-0.382683 0 0.923880"/>
    <limit effort="10000000" lower="0.0" upper="0.1778" velocity="1000"/>
  </joint>

  <joint name="joint15" type="prismatic">
    <parent link="base_link"/>
    <child link="link15"/>
    <origin xyz="0 0 0"/>
    <axis xyz="-0.923879 0 0.382683"/>
    <limit effort="10000000" lower="0.0" upper="0.1778" velocity="1000"/>
  </joint>

  <joint name="joint16" type="prismatic">
    <parent link="base_link"/>
    <child link="link16"/>
    <origin xyz="0 0 0"/>
    <axis xyz="-0.923879 0 -0.382683"/>
    <limit effort="10000000" lower="0.0" upper="0.1778" velocity="1000"/>
  </joint>

  <transmission name="tran1">
    <type>transmission_interface/SimpleTransmission</type>
    <joint name="joint1">
      <hardwareInterface>hardware_interface/EffortJointInterface</hardwareInterface>
    </joint>
    <actuator name="motor1">
      <hardwareInterface>hardware_interface/EffortJointInterface</hardwareInterface>
      <mechanicalReduction>1</mechanicalReduction>
    </actuator>
  </transmission>

  <transmission name="tran2">
    <type>transmission_interface/SimpleTransmission</type>
    <joint name="joint2">
      <hardwareInterface>hardware_interface/EffortJointInterface</hardwareInterface>
    </joint>
    <actuator name="motor2">
      <hardwareInterface>hardware_interface/EffortJointInterface</hardwareInterface>
      <mechanicalReduction>1</mechanicalReduction>
    </actuator>
  </transmission>

  <transmission name="tran3">
    <type>transmission_interface/SimpleTransmission</type>
    <joint name="joint3">
      <hardwareInterface>hardware_interface/EffortJointInterface</hardwareInterface>
    </joint>
    <actuator name="motor3">
      <hardwareInterface>hardware_interface/EffortJointInterface</hardwareInterface>
      <mechanicalReduction>1</mechanicalReduction>
    </actuator>
  </transmission>

  <transmission name="tran4">
    <type>transmission_interface/SimpleTransmission</type>
    <joint name="joint4">
      <hardwareInterface>hardware_interface/EffortJointInterface</hardwareInterface>
    </joint>
    <actuator name="motor4">
      <hardwareInterface>hardware_interface/EffortJointInterface</hardwareInterface>
      <mechanicalReduction>1</mechanicalReduction>
    </actuator>
  </transmission>

  <transmission name="tran5">
    <type>transmission_interface/SimpleTransmission</type>
    <joint name="joint5">
      <hardwareInterface>hardware_interface/EffortJointInterface</hardwareInterface>
    </joint>
    <actuator name="motor5">
      <hardwareInterface>hardware_interface/EffortJointInterface</hardwareInterface>
      <mechanicalReduction>1</mechanicalReduction>
    </actuator>
  </transmission>

  <transmission name="tran6">
    <type>transmission_interface/SimpleTransmission</type>
    <joint name="joint6">
      <hardwareInterface>hardware_interface/EffortJointInterface</hardwareInterface>
    </joint>
    <actuator name="motor6">
      <hardwareInterface>hardware_interface/EffortJointInterface</hardwareInterface>
      <mechanicalReduction>1</mechanicalReduction>
    </actuator>
  </transmission>

  <transmission name="tran7">
    <type>transmission_interface/SimpleTransmission</type>
    <joint name="joint7">
      <hardwareInterface>hardware_interface/EffortJointInterface</hardwareInterface>
    </joint>
    <actuator name="motor7">
      <hardwareInterface>hardware_interface/EffortJointInterface</hardwareInterface>
      <mechanicalReduction>1</mechanicalReduction>
    </actuator>
  </transmission>

  <transmission name="tran8">
    <type>transmission_interface/SimpleTransmission</type>
    <joint name="joint8">
      <hardwareInterface>hardware_interface/EffortJointInterface</hardwareInterface>
    </joint>
    <actuator name="motor8">
      <hardwareInterface>hardware_interface/EffortJointInterface</hardwareInterface>
      <mechanicalReduction>1</mechanicalReduction>
    </actuator>
  </transmission>

  <transmission name="tran9">
    <type>transmission_interface/SimpleTransmission</type>
    <joint name="joint9">
      <hardwareInterface>hardware_interface/EffortJointInterface</hardwareInterface>
    </joint>
    <actuator name="motor9">
      <hardwareInterface>hardware_interface/EffortJointInterface</hardwareInterface>
      <mechanicalReduction>1</mechanicalReduction>
    </actuator>
  </transmission>

  <transmission name="tran10">
    <type>transmission_interface/SimpleTransmission</type>
    <joint name="joint10">
      <hardwareInterface>hardware_interface/EffortJointInterface</hardwareInterface>
    </joint>
    <actuator name="motor10">
      <hardwareInterface>hardware_interface/EffortJointInterface</hardwareInterface>
      <mechanicalReduction>1</mechanicalReduction>
    </actuator>
  </transmission>

  <transmission name="tran11">
    <type>transmission_interface/SimpleTransmission</type>
    <joint name="joint11">
      <hardwareInterface>hardware_interface/EffortJointInterface</hardwareInterface>
    </joint>
    <actuator name="motor11">
      <hardwareInterface>hardware_interface/EffortJointInterface</hardwareInterface>
      <mechanicalReduction>1</mechanicalReduction>
    </actuator>
  </transmission>

  <transmission name="tran12">
    <type>transmission_interface/SimpleTransmission</type>
    <joint name="joint12">
      <hardwareInterface>hardware_interface/EffortJointInterface</hardwareInterface>
    </joint>
    <actuator name="motor12">
      <hardwareInterface>hardware_interface/EffortJointInterface</hardwareInterface>
      <mechanicalReduction>1</mechanicalReduction>
    </actuator>
  </transmission>

  <transmission name="tran13">
    <type>transmission_interface/SimpleTransmission</type>
    <joint name="joint13">
      <hardwareInterface>hardware_interface/EffortJointInterface</hardwareInterface>
    </joint>
    <actuator name="motor13">
      <hardwareInterface>hardware_interface/EffortJointInterface</hardwareInterface>
      <mechanicalReduction>1</mechanicalReduction>
    </actuator>
  </transmission>

  <transmission name="tran14">
    <type>transmission_interface/SimpleTransmission</type>
    <joint name="joint14">
      <hardwareInterface>hardware_interface/EffortJointInterface</hardwareInterface>
    </joint>
    <actuator name="motor14">
      <hardwareInterface>hardware_interface/EffortJointInterface</hardwareInterface>
      <mechanicalReduction>1</mechanicalReduction>
    </actuator>
  </transmission>

  <transmission name="tran15">
    <type>transmission_interface/SimpleTransmission</type>
    <joint name="joint15">
      <hardwareInterface>hardware_interface/EffortJointInterface</hardwareInterface>
    </joint>
    <actuator name="motor15">
      <hardwareInterface>hardware_interface/EffortJointInterface</hardwareInterface>
      <mechanicalReduction>1</mechanicalReduction>
    </actuator>
  </transmission>

  <transmission name="tran16">
    <type>transmission_interface/SimpleTransmission</type>
    <joint name="joint16">
      <hardwareInterface>hardware_interface/EffortJointInterface</hardwareInterface>
    </joint>
    <actuator name="motor16">
      <hardwareInterface>hardware_interface/EffortJointInterface</hardwareInterface>
      <mechanicalReduction>1</mechanicalReduction>
    </actuator>
  </transmission>

	<link name="uwb_link1">
	  <inertial>
		<mass value="0.00001"/>
		<origin rpy="0 0 0" xyz="0 0 0"/>
		<inertia ixx="0" ixy="0" ixz="0" iyy="0" iyz="0" izz="0"/>
	  </inertial>
	  <visual>
		<origin rpy="0 0 0" xyz="0 0 0"/>
		<geometry>
		  <box size="0.01 0.01 0.01"/>
		</geometry>
	  </visual>
	  <collision>
		<origin rpy="0 0 0" xyz="0 0 0"/>
		<geometry>
		  <box size=".01 .01 .01"/>
		</geometry>
	  </collision>
	</link>

	<link name="uwb_link2">
	  <inertial>
		<mass value="0.00001"/>
		<origin rpy="0 0 0" xyz="-0 0 0"/>
		<inertia ixx="0" ixy="0" ixz="0" iyy="0" iyz="0" izz="0"/>
	  </inertial>
	  <visual>
		<origin rpy="0 0 0" xyz="-0 0 0"/>
		<geometry>
		  <box size="0.01 0.01 0.01"/>
		</geometry>
	  </visual>
	  <collision>
		<origin rpy="0 0 0" xyz="-0 0 0"/>
		<geometry>
		  <box size="0.01 0.01 0.01"/>
		</geometry>
	  </collision>
	</link>

  <joint name="uwb_joint1" type="revolute">
     <parent link="base_link"/>
     <child link="uwb_link1"/>
     <origin xyz="0.2 0 0" rpy="0 0 0"/>
     <limit lower="0" upper="0" effort="0" velocity="0"/>
     <axis xyz="0 0 0"/>
   </joint>

  <joint name="uwb_joint2" type="revolute">
     <parent link="base_link"/>
     <child link="uwb_link2"/>
     <origin xyz="-0.2 0 0" rpy="0 0 0"/>
     <limit lower="0" upper="0" effort="0" velocity="0"/>
     <axis xyz="0 0 0"/>
   </joint>

	<link name="imu_link">
	  <inertial>
		<mass value="0.001"/>
		<origin rpy="0 0 0" xyz="0 0 0"/>
		<inertia ixx="0.0001" ixy="0" ixz="0" iyy="0.000001" iyz="0" izz="0.0001"/>
	  </inertial>
	  <visual>
		<origin rpy="0 0 0" xyz="0 0 0"/>
		<geometry>
		  <box size="0.01 0.01 0.01"/>
		</geometry>
	  </visual>
	  <collision>
		<origin rpy="0 0 0" xyz="0 0 0"/>
		<geometry>
		  <box size=".01 .01 .01"/>
		</geometry>
	  </collision>
	</link>

  <joint name="imu_joint" type="revolute">
     <parent link="base_link"/>
     <child link="imu_link"/>
     <origin xyz="0 0 0" rpy="0 0 0"/>
     <limit lower="0" upper="0" effort="0" velocity="0"/>
     <axis xyz="0 0 0"/>
   </joint>

  <gazebo reference="imu_link">
    <gravity>true</gravity>
    <sensor name="imu_sensor" type="imu">
      <always_on>true</always_on>
      <update_rate>100</update_rate>
      <visualize>true</visualize>
      <topic>__default_topic__</topic>
      <plugin filename="libgazebo_ros_imu_sensor.so" name="imu_plugin">
        <topicName>/imu/data_raw</topicName>
        <bodyName>imu_link</bodyName>
        <updateRateHZ>10.0</updateRateHZ>
        <gaussianNoise>0.0</gaussianNoise>
        <xyzOffset>0 0 0</xyzOffset>
        <rpyOffset>0 0 0</rpyOffset>
        <frameName>imu_link</frameName>
        <initialOrientationAsReference>false</initialOrientationAsReference>
      </plugin>
      <pose>0 0 0 0 0 0</pose>
    </sensor>
  </gazebo>

    <!-- ros_control plugin -->
<gazebo>
  <plugin name="gazebo_ros_control" filename="libgazebo_ros_control.so">
    <robotSimType>gazebo_ros_control/DefaultRobotHWSim</robotSimType>
  </plugin>
</gazebo>
  
</robot>
