<?xml version="1.0"?>
<robot name="rolling_robot">

  <material name="grey">
    <color rgba="0.5 0.5 0.5 0.5"/>
  </material>
  
  <link name="dummy">
  </link>
  
  <link name="base_link">
    <visual>
      <geometry>
	<mesh filename="/home/eric/rolling_robot/rolling_robot_model/rhombicuboctahedron.stl" scale="0.025641 0.025641 0.025641"/>
      </geometry>
      <origin xyz="0 0 0"/>
      <material name="grey"/>
    </visual>
    <collision>
      <geometry>
	<mesh filename="/home/eric/rolling_robot/rolling_robot_model/rhombicuboctahedron.stl" scale="0.025641 0.025641 0.025641"/>
      </geometry>
    </collision>
    <inertial>
      <mass value="20"/>
      <inertia ixx="3.3334" ixy="0.0" ixz="0.0" iyy="3.3334" iyz="0.0" izz="3.3334"/>
    </inertial>
  </link>
  
  <joint name="dummy_joint" type="fixed">
     <parent link="dummy"/>
     <child link="base_link"/>
   </joint>

  <link name="link1">
    <visual>
      <geometry>
        <cylinder length="0.1778" radius="0.005"/>
      </geometry>
      <origin rpy="-0.392699 -0 -0" xyz="0 -0.094 -0.224703"/>
      <material name="grey"/>
    </visual>
    <collision>
      <geometry>
	    <cylinder length="0.1778" radius="0.005"/>
      </geometry>
      <origin rpy="-0.392699 -0 -0" xyz="0 -0.094 -0.224703"/>
    </collision>
    <inertial>
      <mass value="0.1"/>
    <inertia ixx="0.00026407" ixy="0.0" ixz="0.0" iyy="0.00026407" iyz="0.0" izz="0.00026407"/>
    </inertial>
  </link>

  <link name="link2">
    <visual>
      <geometry>
        <cylinder length="0.1778" radius="0.005"/>
      </geometry>
      <origin rpy="0.392699 -0 -0" xyz="0 0.094 -0.224703"/>
      <material name="grey"/>
    </visual>
    <collision>
      <geometry>
	    <cylinder length="0.1778" radius="0.005"/>
      </geometry>
      <origin rpy="0.392699 -0 -0" xyz="0 0.094 -0.224703"/>
    </collision>
    <inertial>
      <mass value="0.1"/>
    <inertia ixx="0.00026407" ixy="0.0" ixz="0.0" iyy="0.00026407" iyz="0.0" izz="0.00026407"/>
    </inertial>
  </link>

  <link name="link3">
    <visual>
      <geometry>
        <cylinder length="0.1778" radius="0.005"/>
      </geometry>
      <origin rpy="1.178097 0 0" xyz="0 0.221 -0.088000"/>
      <material name="grey"/>
    </visual>
    <collision>
      <geometry>
	    <cylinder length="0.1778" radius="0.005"/>
      </geometry>
      <origin rpy="1.178097 0 0" xyz="0 0.221 -0.088000"/>
    </collision>
    <inertial>
      <mass value="0.1"/>
    <inertia ixx="0.00026407" ixy="0.0" ixz="0.0" iyy="0.00026407" iyz="0.0" izz="0.00026407"/>
    </inertial>
  </link>


  <link name="link4">
    <visual>
      <geometry>
        <cylinder length="0.1778" radius="0.005"/>
      </geometry>
      <origin rpy="1.963495 0 0" xyz="0 0.221 0.088000"/>
      <material name="grey"/>
    </visual>
    <collision>
      <geometry>
	    <cylinder length="0.1778" radius="0.005"/>
      </geometry>
      <origin rpy="1.963495 0 0" xyz="0 0.221 0.088000"/>
    </collision>
    <inertial>
      <mass value="0.1"/>
    <inertia ixx="0.00026407" ixy="0.0" ixz="0.0" iyy="0.00026407" iyz="0.0" izz="0.00026407"/>
    </inertial>
  </link>

  <link name="link5">
    <visual>
      <geometry>
        <cylinder length="0.1778" radius="0.005"/>
      </geometry>
      <origin rpy="2.748894 0 0" xyz="0 0.094 0.224703"/>
      <material name="grey"/>
    </visual>
    <collision>
      <geometry>
	    <cylinder length="0.1778" radius="0.005"/>
      </geometry>
      <origin rpy="2.748894 0 0" xyz="0 0.094 0.224703"/>
    </collision>
    <inertial>
      <mass value="0.1"/>
    <inertia ixx="0.00026407" ixy="0.0" ixz="0.0" iyy="0.00026407" iyz="0.0" izz="0.00026407"/>
    </inertial>
  </link>
 
  <link name="link6">
    <visual>
      <geometry>
        <cylinder length="0.1778" radius="0.005"/>
      </geometry>
      <origin rpy="-2.748894 0 0" xyz="0 -0.094 0.224703"/>
      <material name="grey"/>
    </visual>
    <collision>
      <geometry>
	    <cylinder length="0.1778" radius="0.005"/>
      </geometry>
      <origin rpy="-2.748894 0 0" xyz="0 -0.094 0.224703"/>
    </collision>
    <inertial>
      <mass value="0.1"/>
    <inertia ixx="0.00026407" ixy="0.0" ixz="0.0" iyy="0.00026407" iyz="0.0" izz="0.00026407"/>
    </inertial>
  </link>

  <link name="link7">
    <visual>
      <geometry>
        <cylinder length="0.1778" radius="0.005"/>
      </geometry>
      <origin rpy="-1.963495 0 0" xyz="0 -0.221 0.088000"/>
      <material name="grey"/>
    </visual>
    <collision>
      <geometry>
	    <cylinder length="0.1778" radius="0.005"/>
      </geometry>
      <origin rpy="-1.963495 0 0" xyz="0 -0.221 0.088000"/>
    </collision>
    <inertial>
      <mass value="0.1"/>
    <inertia ixx="0.00026407" ixy="0.0" ixz="0.0" iyy="0.00026407" iyz="0.0" izz="0.00026407"/>
    </inertial>
  </link>

  <link name="link8">
    <visual>
      <geometry>
        <cylinder length="0.1778" radius="0.005"/>
      </geometry>
      <origin rpy="-1.178097 0 0" xyz="0 -0.221 -0.088000"/>
      <material name="grey"/>
    </visual>
    <collision>
      <geometry>
	    <cylinder length="0.1778" radius="0.005"/>
      </geometry>
      <origin rpy="-1.178097 0 0" xyz="0 -0.221 -0.088000"/>
    </collision>
    <inertial>
      <mass value="0.1"/>
    <inertia ixx="0.00026407" ixy="0.0" ixz="0.0" iyy="0.00026407" iyz="0.0" izz="0.00026407"/>
    </inertial>
  </link>

  <joint name="joint1" type="prismatic">
    <parent link="base_link"/>
    <child link="link1"/>
    <origin xyz="0 0 0"/>
    <axis xyz="0 -0.382683 -0.923880"/>
    <limit effort="10000000" lower="0.0" upper="0.1778" velocity="1000"/>
  </joint>

  <joint name="joint2" type="prismatic">
    <parent link="base_link"/>
    <child link="link2"/>
    <origin xyz="0 0 0"/>
    <axis xyz="0 0.382683 -0.923880"/>
    <limit effort="10000000" lower="0.0" upper="0.1778" velocity="1000"/>
  </joint>

  <joint name="joint3" type="prismatic">
    <parent link="base_link"/>
    <child link="link3"/>
    <origin xyz="0 0 0"/>
    <axis xyz="0 0.923879 -0.382683"/>
    <limit effort="10000000" lower="0.0" upper="0.1778" velocity="1000"/>
  </joint>

  <joint name="joint4" type="prismatic">
    <parent link="base_link"/>
    <child link="link4"/>
    <origin xyz="0 0 0"/>
    <axis xyz="0 0.923879 0.382683"/>
    <limit effort="10000000" lower="0.0" upper="0.1778" velocity="1000"/>
  </joint>

  <joint name="joint5" type="prismatic">
    <parent link="base_link"/>
    <child link="link5"/>
    <origin xyz="0 0 0"/>
    <axis xyz="0 0.382683 0.923880"/>
    <limit effort="10000000" lower="0.0" upper="0.1778" velocity="1000"/>
  </joint>

  <joint name="joint6" type="prismatic">
    <parent link="base_link"/>
    <child link="link6"/>
    <origin xyz="0 0 0"/>
    <axis xyz="0 -0.382683 0.923880"/>
    <limit effort="10000000" lower="0.0" upper="0.1778" velocity="1000"/>
  </joint>

  <joint name="joint7" type="prismatic">
    <parent link="base_link"/>
    <child link="link7"/>
    <origin xyz="0 0 0"/>
    <axis xyz="0 -0.923879 0.382683"/>
    <limit effort="10000000" lower="0.0" upper="0.1778" velocity="1000"/>
  </joint>

  <joint name="joint8" type="prismatic">
    <parent link="base_link"/>
    <child link="link8"/>
    <origin xyz="0 0 0"/>
    <axis xyz="0 -0.923879 -0.382683"/>
    <limit effort="10000000" lower="0.0" upper="0.1778" velocity="1000"/>
  </joint>

  <transmission name="tran1">
    <type>transmission_interface/SimpleTransmission</type>
    <joint name="joint1">
      <hardwareInterface>hardware_interface/EffortJointInterface</hardwareInterface>
    </joint>
    <actuator name="motor1">
      <hardwareInterface>hardware_interface/EffortJointInterface</hardwareInterface>
      <mechanicalReduction>1</mechanicalReduction>
    </actuator>
  </transmission>

  <transmission name="tran2">
    <type>transmission_interface/SimpleTransmission</type>
    <joint name="joint2">
      <hardwareInterface>hardware_interface/EffortJointInterface</hardwareInterface>
    </joint>
    <actuator name="motor2">
      <hardwareInterface>hardware_interface/EffortJointInterface</hardwareInterface>
      <mechanicalReduction>1</mechanicalReduction>
    </actuator>
  </transmission>

  <transmission name="tran3">
    <type>transmission_interface/SimpleTransmission</type>
    <joint name="joint3">
      <hardwareInterface>hardware_interface/EffortJointInterface</hardwareInterface>
    </joint>
    <actuator name="motor3">
      <hardwareInterface>hardware_interface/EffortJointInterface</hardwareInterface>
      <mechanicalReduction>1</mechanicalReduction>
    </actuator>
  </transmission>

  <transmission name="tran4">
    <type>transmission_interface/SimpleTransmission</type>
    <joint name="joint4">
      <hardwareInterface>hardware_interface/EffortJointInterface</hardwareInterface>
    </joint>
    <actuator name="motor4">
      <hardwareInterface>hardware_interface/EffortJointInterface</hardwareInterface>
      <mechanicalReduction>1</mechanicalReduction>
    </actuator>
  </transmission>

  <transmission name="tran5">
    <type>transmission_interface/SimpleTransmission</type>
    <joint name="joint5">
      <hardwareInterface>hardware_interface/EffortJointInterface</hardwareInterface>
    </joint>
    <actuator name="motor5">
      <hardwareInterface>hardware_interface/EffortJointInterface</hardwareInterface>
      <mechanicalReduction>1</mechanicalReduction>
    </actuator>
  </transmission>

  <transmission name="tran6">
    <type>transmission_interface/SimpleTransmission</type>
    <joint name="joint6">
      <hardwareInterface>hardware_interface/EffortJointInterface</hardwareInterface>
    </joint>
    <actuator name="motor6">
      <hardwareInterface>hardware_interface/EffortJointInterface</hardwareInterface>
      <mechanicalReduction>1</mechanicalReduction>
    </actuator>
  </transmission>

  <transmission name="tran7">
    <type>transmission_interface/SimpleTransmission</type>
    <joint name="joint7">
      <hardwareInterface>hardware_interface/EffortJointInterface</hardwareInterface>
    </joint>
    <actuator name="motor7">
      <hardwareInterface>hardware_interface/EffortJointInterface</hardwareInterface>
      <mechanicalReduction>1</mechanicalReduction>
    </actuator>
  </transmission>

  <transmission name="tran8">
    <type>transmission_interface/SimpleTransmission</type>
    <joint name="joint8">
      <hardwareInterface>hardware_interface/EffortJointInterface</hardwareInterface>
    </joint>
    <actuator name="motor8">
      <hardwareInterface>hardware_interface/EffortJointInterface</hardwareInterface>
      <mechanicalReduction>1</mechanicalReduction>
    </actuator>
  </transmission>

    <!-- ros_control plugin -->
<gazebo>
  <plugin name="gazebo_ros_control" filename="libgazebo_ros_control.so">
    <robotSimType>gazebo_ros_control/DefaultRobotHWSim</robotSimType>
  </plugin>
</gazebo>
  
</robot>
